<?xml version="1.0" encoding="utf-8"?>
<robot name="xarm_6">
  
  <!-- Base Link -->
  <link name="base_link">
    <inertial>
      <origin xyz="0 0 0.05" rpy="0 0 0" />
      <mass value="2.5" />
      <inertia
        ixx="0.00208333" ixy="0" ixz="0"
        iyy="0.00208333" iyz="0"
        izz="0.00208333" />
    </inertial>
    <visual>
      <origin xyz="0 0 0.05" rpy="0 0 0" />
      <geometry>
        <cylinder radius="0.08" length="0.1" />
      </geometry>
      <material name="base_material">
        <color rgba="0.2 0.2 0.2 1" />
      </material>
    </visual>
    <collision>
      <origin xyz="0 0 0.05" rpy="0 0 0" />
      <geometry>
        <cylinder radius="0.08" length="0.1" />
      </geometry>
    </collision>
  </link>

  <!-- Link 1 -->
  <link name="link1">
    <inertial>
      <origin xyz="0 0 0.1" rpy="0 0 0" />
      <mass value="1.8" />
      <inertia
        ixx="0.00520833" ixy="0" ixz="0"
        iyy="0.00520833" iyz="0"
        izz="0.00208333" />
    </inertial>
    <visual>
      <origin xyz="0 0 0.1" rpy="0 0 0" />
      <geometry>
        <cylinder radius="0.06" length="0.2" />
      </geometry>
      <material name="link_material">
        <color rgba="0.7 0.7 0.7 1" />
      </material>
    </visual>
    <collision>
      <origin xyz="0 0 0.1" rpy="0 0 0" />
      <geometry>
        <cylinder radius="0.06" length="0.2" />
      </geometry>
    </collision>
  </link>

  <!-- Joint 1: Base to Link1 -->
  <joint name="joint1" type="revolute">
    <origin xyz="0 0 0.1" rpy="0 0 0" />
    <parent link="base_link" />
    <child link="link1" />
    <axis xyz="0 0 1" />
    <limit lower="-6.28" upper="6.28" effort="50" velocity="3.14" />
  </joint>

  <!-- Link 2 -->
  <link name="link2">
    <inertial>
      <origin xyz="0.15 0 0" rpy="0 0 0" />
      <mass value="1.5" />
      <inertia
        ixx="0.00208333" ixy="0" ixz="0"
        iyy="0.00781250" iyz="0"
        izz="0.00781250" />
    </inertial>
    <visual>
      <origin xyz="0.15 0 0" rpy="0 1.5708 0" />
      <geometry>
        <cylinder radius="0.05" length="0.3" />
      </geometry>
      <material name="link_material">
        <color rgba="0.7 0.7 0.7 1" />
      </material>
    </visual>
    <collision>
      <origin xyz="0.15 0 0" rpy="0 1.5708 0" />
      <geometry>
        <cylinder radius="0.05" length="0.3" />
      </geometry>
    </collision>
  </link>

  <!-- Joint 2: Link1 to Link2 -->
  <joint name="joint2" type="revolute">
    <origin xyz="0 0 0.2" rpy="1.5708 0 0" />
    <parent link="link1" />
    <child link="link2" />
    <axis xyz="0 0 1" />
    <limit lower="-2.09" upper="2.09" effort="50" velocity="3.14" />
  </joint>

  <!-- Link 3 -->
  <link name="link3">
    <inertial>
      <origin xyz="0.125 0 0" rpy="0 0 0" />
      <mass value="1.2" />
      <inertia
        ixx="0.00208333" ixy="0" ixz="0"
        iyy="0.00520833" iyz="0"
        izz="0.00520833" />
    </inertial>
    <visual>
      <origin xyz="0.125 0 0" rpy="0 1.5708 0" />
      <geometry>
        <cylinder radius="0.045" length="0.25" />
      </geometry>
      <material name="link_material">
        <color rgba="0.7 0.7 0.7 1" />
      </material>
    </visual>
    <collision>
      <origin xyz="0.125 0 0" rpy="0 1.5708 0" />
      <geometry>
        <cylinder radius="0.045" length="0.25" />
      </geometry>
    </collision>
  </link>

  <!-- Joint 3: Link2 to Link3 -->
  <joint name="joint3" type="revolute">
    <origin xyz="0.3 0 0" rpy="0 0 0" />
    <parent link="link2" />
    <child link="link3" />
    <axis xyz="0 0 1" />
    <limit lower="-6.28" upper="6.28" effort="30" velocity="3.14" />
  </joint>

  <!-- Link 4 -->
  <link name="link4">
    <inertial>
      <origin xyz="0 0 0.08" rpy="0 0 0" />
      <mass value="0.8" />
      <inertia
        ixx="0.00208333" ixy="0" ixz="0"
        iyy="0.00208333" iyz="0"
        izz="0.00104167" />
    </inertial>
    <visual>
      <origin xyz="0 0 0.08" rpy="0 0 0" />
      <geometry>
        <cylinder radius="0.04" length="0.16" />
      </geometry>
      <material name="link_material">
        <color rgba="0.7 0.7 0.7 1" />
      </material>
    </visual>
    <collision>
      <origin xyz="0 0 0.08" rpy="0 0 0" />
      <geometry>
        <cylinder radius="0.04" length="0.16" />
      </geometry>
    </collision>
  </link>

  <!-- Joint 4: Link3 to Link4 -->
  <joint name="joint4" type="revolute">
    <origin xyz="0.25 0 0" rpy="-1.5708 0 0" />
    <parent link="link3" />
    <child link="link4" />
    <axis xyz="0 0 1" />
    <limit lower="-6.28" upper="6.28" effort="30" velocity="3.14" />
  </joint>

  <!-- Link 5 -->
  <link name="link5">
    <inertial>
      <origin xyz="0 0 0.06" rpy="0 0 0" />
      <mass value="0.6" />
      <inertia
        ixx="0.00104167" ixy="0" ixz="0"
        iyy="0.00104167" iyz="0"
        izz="0.00052083" />
    </inertial>
    <visual>
      <origin xyz="0 0 0.06" rpy="0 0 0" />
      <geometry>
        <cylinder radius="0.035" length="0.12" />
      </geometry>
      <material name="link_material">
        <color rgba="0.7 0.7 0.7 1" />
      </material>
    </visual>
    <collision>
      <origin xyz="0 0 0.06" rpy="0 0 0" />
      <geometry>
        <cylinder radius="0.035" length="0.12" />
      </geometry>
    </collision>
  </link>

  <!-- Joint 5: Link4 to Link5 -->
  <joint name="joint5" type="revolute">
    <origin xyz="0 0 0.16" rpy="1.5708 0 0" />
    <parent link="link4" />
    <child link="link5" />
    <axis xyz="0 0 1" />
    <limit lower="-1.69" upper="3.84" effort="20" velocity="3.14" />
  </joint>

  <!-- Link 6 (End Effector) -->
  <link name="link6">
    <inertial>
      <origin xyz="0 0 0.04" rpy="0 0 0" />
      <mass value="0.4" />
      <inertia
        ixx="0.00052083" ixy="0" ixz="0"
        iyy="0.00052083" iyz="0"
        izz="0.00026042" />
    </inertial>
    <visual>
      <origin xyz="0 0 0.04" rpy="0 0 0" />
      <geometry>
        <cylinder radius="0.03" length="0.08" />
      </geometry>
      <material name="end_effector_material">
        <color rgba="0.9 0.9 0.9 1" />
      </material>
    </visual>
    <collision>
      <origin xyz="0 0 0.04" rpy="0 0 0" />
      <geometry>
        <cylinder radius="0.03" length="0.08" />
      </geometry>
    </collision>
  </link>

  <!-- Joint 6: Link5 to Link6 -->
  <joint name="joint6" type="revolute">
    <origin xyz="0 0 0.12" rpy="-1.5708 0 0" />
    <parent link="link5" />
    <child link="link6" />
    <axis xyz="0 0 1" />
    <limit lower="-6.28" upper="6.28" effort="20" velocity="3.14" />
  </joint>

  <!-- Tool Center Point (TCP) -->
  <link name="tcp_link" />
  
  <joint name="tcp_joint" type="fixed">
    <origin xyz="0 0 0.08" rpy="0 0 0" />
    <parent link="link6" />
    <child link="tcp_link" />
  </joint>

  <!-- Optional Gripper Link -->
  <link name="gripper_link">
    <inertial>
      <origin xyz="0 0 0.03" rpy="0 0 0" />
      <mass value="0.2" />
      <inertia
        ixx="0.00013" ixy="0" ixz="0"
        iyy="0.00013" iyz="0"
        izz="0.00013" />
    </inertial>
    <visual>
      <origin xyz="0 0 0.03" rpy="0 0 0" />
      <geometry>
        <box size="0.06 0.02 0.06" />
      </geometry>
      <material name="gripper_material">
        <color rgba="0.2 0.2 0.8 1" />
      </material>
    </visual>
    <collision>
      <origin xyz="0 0 0.03" rpy="0 0 0" />
      <geometry>
        <box size="0.06 0.02 0.06" />
      </geometry>
    </collision>
  </link>

  <!-- Gripper Joint -->
  <joint name="gripper_joint" type="fixed">
    <origin xyz="0 0 0.08" rpy="0 0 0" />
    <parent link="link6" />
    <child link="gripper_link" />
  </joint>

</robot>